I'm sorry, but an uncaught exception occurred.

While running game code:
  File "game/code/scene (11)/scene11.rpy", line 50, in script
    show генто нейтральний ai right2 with dissolve
Exception: Image 'генто нейтральний' does not accept attributes 'ai right2'.

-- Full Traceback ------------------------------------------------------------

Full traceback:
  File "game/code/scene (11)/scene11.rpy", line 50, in script
    show генто нейтральний ai right2 with dissolve
  File "C:\Programs\RenPy\renpy-8.0.3-sdk\renpy\ast.py", line 1408, in execute
    show_imspec(self.imspec, atl=getattr(self, "atl", None))
  File "C:\Programs\RenPy\renpy-8.0.3-sdk\renpy\ast.py", line 1371, in show_imspec
    renpy.config.show(name,
  File "C:\Programs\RenPy\renpy-8.0.3-sdk\renpy\exports.py", line 686, in show
    if not base.find_target() and renpy.config.missing_show:
  File "C:\Programs\RenPy\renpy-8.0.3-sdk\renpy\display\image.py", line 414, in find_target
    self.target = target._duplicate(a)
  File "C:\Programs\RenPy\renpy-8.0.3-sdk\renpy\display\core.py", line 397, in _duplicate
    args.extraneous()
  File "C:\Programs\RenPy\renpy-8.0.3-sdk\renpy\display\core.py", line 265, in extraneous
    raise Exception("Image '{}' does not accept attributes '{}'.".format(
Exception: Image 'генто нейтральний' does not accept attributes 'ai right2'.

Windows-10-10.0.22000 AMD64
Ren'Py 8.0.3.22090809
Прощавай, Оазо 
Sun Feb 12 14:35:26 2023
